package com.example;

public class MyFirstException {


    public int divide(int numberToDivide, int numberToDivideBy)
    throws BadNumberException{
        if(numberToDivideBy == 0){
            throw new BadNumberException("Cannot divide by 0");
        }
        return numberToDivide / numberToDivideBy;
    }
 


public void callDivide(){
    try {
        int result = divide(2,1);
        System.out.println(result);
    } catch (BadNumberException e) {
        //do something clever with the exception
        System.out.println(e.getMessage());
    }
    System.out.println("Division attempt done");
}


private void testMyOwnException() throws CleoException {
	throw new CleoException("My own exception that I can hold the control");
}


public static void main(String args[]) throws CleoException{
	try {
		new MyFirstException().testMyOwnException();
	} catch (Exception e) {
		// TODO Auto-generated catch block
		e.printStackTrace();
	}
	//MyFirstException myFirstException = new MyFirstException();
	//myFirstException.callDivide();
	
}
}